2023-04-19 12:18:57,719 INFO    MainThread:7870 [wandb_setup.py:_flush():76] Configure stats pid to 7870
2023-04-19 12:18:57,720 INFO    MainThread:7870 [wandb_setup.py:_flush():76] Loading settings from /opt/ml/.config/wandb/settings
2023-04-19 12:18:57,720 INFO    MainThread:7870 [wandb_setup.py:_flush():76] Loading settings from /opt/ml/level1_imageclassification-cv-17/wandb/settings
2023-04-19 12:18:57,720 INFO    MainThread:7870 [wandb_setup.py:_flush():76] Loading settings from environment variables: {}
2023-04-19 12:18:57,720 INFO    MainThread:7870 [wandb_setup.py:_flush():76] Applying setup settings: {'_disable_service': False}
2023-04-19 12:18:57,720 INFO    MainThread:7870 [wandb_setup.py:_flush():76] Inferring run settings from compute environment: {'program_relpath': 'train.py', 'program': 'train.py'}
2023-04-19 12:18:57,720 INFO    MainThread:7870 [wandb_init.py:_log_setup():507] Logging user logs to /opt/ml/level1_imageclassification-cv-17/wandb/run-20230419_121857-ldltspfa/logs/debug.log
2023-04-19 12:18:57,720 INFO    MainThread:7870 [wandb_init.py:_log_setup():508] Logging internal logs to /opt/ml/level1_imageclassification-cv-17/wandb/run-20230419_121857-ldltspfa/logs/debug-internal.log
2023-04-19 12:18:57,720 INFO    MainThread:7870 [wandb_init.py:init():547] calling init triggers
2023-04-19 12:18:57,720 INFO    MainThread:7870 [wandb_init.py:init():554] wandb.init called with sweep_config: {}
config: {'seed': 111, 'epochs': 1, 'dataset': 'MaskGenderDataset', 'augmentation': 'YoonpyoAugmentation', 'resize': (512, 384), 'batch_size': 32, 'valid_batch_size': 32, 'model': 'EfficientNetB3', 'optimizer': 'Adam', 'lr': 1e-05, 'val_ratio': 0.2, 'criterion': 'label_smoothing', 'lr_decay_step': 20, 'log_interval': 20, 'name': 'test', 'model_dir': './test', 'patience_limit': 3}
2023-04-19 12:18:57,720 INFO    MainThread:7870 [wandb_init.py:init():595] starting backend
2023-04-19 12:18:57,720 INFO    MainThread:7870 [wandb_init.py:init():599] setting up manager
2023-04-19 12:18:57,723 INFO    MainThread:7870 [backend.py:_multiprocessing_setup():106] multiprocessing start_methods=fork,spawn,forkserver, using: spawn
2023-04-19 12:18:57,724 INFO    MainThread:7870 [wandb_init.py:init():605] backend started and connected
2023-04-19 12:18:57,728 INFO    MainThread:7870 [wandb_init.py:init():695] updated telemetry
2023-04-19 12:18:57,792 INFO    MainThread:7870 [wandb_init.py:init():732] communicating run to backend with 60.0 second timeout
2023-04-19 12:19:44,821 INFO    Thread-2  :7870 [retry.py:__call__():172] Retry attempt failed:
Traceback (most recent call last):
  File "/opt/conda/lib/python3.8/site-packages/urllib3/connectionpool.py", line 426, in _make_request
    six.raise_from(e, None)
  File "<string>", line 3, in raise_from
  File "/opt/conda/lib/python3.8/site-packages/urllib3/connectionpool.py", line 421, in _make_request
    httplib_response = conn.getresponse()
  File "/opt/conda/lib/python3.8/http/client.py", line 1347, in getresponse
    response.begin()
  File "/opt/conda/lib/python3.8/http/client.py", line 307, in begin
    version, status, reason = self._read_status()
  File "/opt/conda/lib/python3.8/http/client.py", line 268, in _read_status
    line = str(self.fp.readline(_MAXLINE + 1), "iso-8859-1")
  File "/opt/conda/lib/python3.8/socket.py", line 669, in readinto
    return self._sock.recv_into(b)
  File "/opt/conda/lib/python3.8/ssl.py", line 1241, in recv_into
    return self.read(nbytes, buffer)
  File "/opt/conda/lib/python3.8/ssl.py", line 1099, in read
    return self._sslobj.read(len, buffer)
socket.timeout: The read operation timed out

During handling of the above exception, another exception occurred:

Traceback (most recent call last):
  File "/opt/conda/lib/python3.8/site-packages/requests/adapters.py", line 439, in send
    resp = conn.urlopen(
  File "/opt/conda/lib/python3.8/site-packages/urllib3/connectionpool.py", line 726, in urlopen
    retries = retries.increment(
  File "/opt/conda/lib/python3.8/site-packages/urllib3/util/retry.py", line 410, in increment
    raise six.reraise(type(error), error, _stacktrace)
  File "/opt/conda/lib/python3.8/site-packages/urllib3/packages/six.py", line 735, in reraise
    raise value
  File "/opt/conda/lib/python3.8/site-packages/urllib3/connectionpool.py", line 670, in urlopen
    httplib_response = self._make_request(
  File "/opt/conda/lib/python3.8/site-packages/urllib3/connectionpool.py", line 428, in _make_request
    self._raise_timeout(err=e, url=url, timeout_value=read_timeout)
  File "/opt/conda/lib/python3.8/site-packages/urllib3/connectionpool.py", line 335, in _raise_timeout
    raise ReadTimeoutError(
urllib3.exceptions.ReadTimeoutError: HTTPSConnectionPool(host='api.wandb.ai', port=443): Read timed out. (read timeout=10)

During handling of the above exception, another exception occurred:

Traceback (most recent call last):
  File "/opt/conda/lib/python3.8/site-packages/wandb/sdk/lib/retry.py", line 131, in __call__
    result = self._call_fn(*args, **kwargs)
  File "/opt/conda/lib/python3.8/site-packages/wandb/sdk/internal/internal_api.py", line 285, in execute
    return self.client.execute(*args, **kwargs)  # type: ignore
  File "/opt/conda/lib/python3.8/site-packages/wandb/vendor/gql-0.2.0/wandb_gql/client.py", line 52, in execute
    result = self._get_result(document, *args, **kwargs)
  File "/opt/conda/lib/python3.8/site-packages/wandb/vendor/gql-0.2.0/wandb_gql/client.py", line 60, in _get_result
    return self.transport.execute(document, *args, **kwargs)
  File "/opt/conda/lib/python3.8/site-packages/wandb/sdk/lib/gql_request.py", line 55, in execute
    request = self.session.post(self.url, **post_args)
  File "/opt/conda/lib/python3.8/site-packages/requests/sessions.py", line 578, in post
    return self.request('POST', url, data=data, json=json, **kwargs)
  File "/opt/conda/lib/python3.8/site-packages/requests/sessions.py", line 530, in request
    resp = self.send(prep, **send_kwargs)
  File "/opt/conda/lib/python3.8/site-packages/requests/sessions.py", line 643, in send
    r = adapter.send(request, **kwargs)
  File "/opt/conda/lib/python3.8/site-packages/requests/adapters.py", line 529, in send
    raise ReadTimeout(e, request=request)
requests.exceptions.ReadTimeout: HTTPSConnectionPool(host='api.wandb.ai', port=443): Read timed out. (read timeout=10)
2023-04-19 12:19:57,809 ERROR   MainThread:7870 [wandb_init.py:init():758] encountered error: Run initialization has timed out after 60.0 sec. 
Please refer to the documentation for additional information: https://docs.wandb.ai/guides/track/tracking-faq#initstarterror-error-communicating-with-wandb-process-
2023-04-19 12:19:58,279 ERROR   MainThread:7870 [wandb_init.py:init():1163] Run initialization has timed out after 60.0 sec. 
Please refer to the documentation for additional information: https://docs.wandb.ai/guides/track/tracking-faq#initstarterror-error-communicating-with-wandb-process-
Traceback (most recent call last):
  File "/opt/conda/lib/python3.8/site-packages/wandb/sdk/wandb_init.py", line 1145, in init
    run = wi.init()
  File "/opt/conda/lib/python3.8/site-packages/wandb/sdk/wandb_init.py", line 764, in init
    raise error
wandb.errors.CommError: Run initialization has timed out after 60.0 sec. 
Please refer to the documentation for additional information: https://docs.wandb.ai/guides/track/tracking-faq#initstarterror-error-communicating-with-wandb-process-
2023-04-19 12:19:59,281 WARNING MsgRouterThr:7870 [router.py:message_loop():77] message_loop has been closed
